<robot name="onshape">
	<link name="torso_1">
		<visual>
			<origin xyz="0 0 0" rpy="0 -0 0" />
			<geometry>
				<mesh filename="package://torso.stl"/>
			</geometry>
			<material name="torso_material">
				<!-- <color rgba="0.615686 0.811765 0.929412 1.0"/> -->
				<color rgba="1 0.706 0 1.0"/>
			</material>
		</visual>
		<collision>
			<origin xyz="0 0 0" rpy="0 -0 0" />
			<geometry>
				<mesh filename="package://torso.stl"/>
			</geometry>
			<material name="torso_material">
				<color rgba="0.615686 0.811765 0.929412 1.0"/>
			</material>
		</collision>
		<inertial>
			<origin xyz="0 0 0.3" rpy="0 0 0"/>
			<mass value="0.8" />
			<inertia ixx="0.001" ixy="0"  ixz="0" iyy="0.001" iyz="0" izz="0.001" />
		</inertial>
	</link>

	<link name="r_wheel_1">
		<visual>
			<origin xyz="-0.02 0 0" rpy="0 -0 0" />
			<geometry>
				<mesh filename="package://r_wheel.stl"/>
			</geometry>
			<material name="r_wheel_material">
				<color rgba="0, 0.651, 0.921 1.0"/>
			</material>
		</visual>
		<collision>
			<origin xyz="-0.02 0 0" rpy="0 -0 0" />
			<geometry>
				<mesh filename="package://r_wheel.stl"/>
			</geometry>
			<material name="r_wheel_material">
				<color rgba="0.615686 0.811765 0.929412 1.0"/>
			</material>
		</collision>
		<inertial>
			<origin xyz="-0.02 0 0" rpy="0 0 0"/>
			<mass value="0.1" />
			<inertia ixx="0.0001" ixy="0"  ixz="0" iyy="0.0001" iyz="0" izz="0.0001" />
		</inertial>
	</link>

	<joint name="lwheel_speed" type="revolute">
		<origin xyz="0.15 0 0.1" rpy="0 -0 0" />
		<parent link="torso_1" />
		<child link="r_wheel_1" />
		<axis xyz="1 0 0"/>
		<limit effort="1000" velocity="0" />
		<joint_properties friction="0.8"/>
	</joint>

	<link name="l_wheel_1">
		<visual>
			<origin xyz="0.02 0 0" rpy="0 -0 0" />
			<geometry>
				<mesh filename="package://l_wheel.stl"/>
			</geometry>
			<material name="l_wheel_material">
				<color rgba="0, 0.651, 0.921 1.0"/>
			</material>
		</visual>
		<collision>
			<origin xyz="0.02 0 0" rpy="0 -0 0" />
			<geometry>
				<mesh filename="package://l_wheel.stl"/>
			</geometry>
			<material name="l_wheel_material">
				<color rgba="0.615686 0.811765 0.929412 1.0"/>
			</material>
		</collision>
		<inertial>
			<origin xyz="0.02 0 0" rpy="0 0 0"/>
			<mass value="0.1" />
			<inertia ixx="0.0001" ixy="0"  ixz="0" iyy="0.0001" iyz="0" izz="0.0001" />
		</inertial>
	</link>

	<joint name="rwheel_speedinv" type="revolute">
		<origin xyz="-0.15 0 0.1" rpy="0 -0 0" />
		<parent link="torso_1" />
		<child link="l_wheel_1" />
		<axis xyz="-1 0 0"/>
		<limit effort="1000" velocity="0" />
		<joint_properties friction="0.8"/>
	</joint>

</robot>
